<?xml version="1.0"?>
<robot name="cam_follower_mechanism">

  <material name="pink">
    <color rgba="1 0.5 0.7 1"/>
  </material>
  <material name="blue">
    <color rgba="0.2 0.4 0.8 1"/>
  </material>
  <material name="light_blue_roller">
    <color rgba="0.5 0.7 1 1"/>
  </material>
  <material name="yellow_handle">
    <color rgba="1 0.9 0.2 1"/>
  </material>
  <material name="grey_metal">
    <color rgba="0.6 0.6 0.6 1"/>
  </material>

  <link name="base_link">
    <visual>
      <geometry>
        <box size="0.3 0.4 0.02"/> </geometry>
      <origin xyz="0 0 -0.01" rpy="0 0 0"/>
      <material name="grey_metal"/>
    </visual>
    <collision>
      <geometry>
        <box size="0.3 0.4 0.02"/>
      </geometry>
      <origin xyz="0 0 -0.01" rpy="0 0 0"/>
    </collision>
    <inertial>
      <mass value="5.0"/>
      <origin xyz="0 0 -0.01"/>
      <inertia ixx="0.1" ixy="0" ixz="0" iyy="0.1" iyz="0" izz="0.1"/>
    </inertial>
  </link>

  <link name="cam_assembly_link">
    <inertial>
      <mass value="1.0"/>
      <origin xyz="0 0 0"/> <inertia ixx="0.01" ixy="0" ixz="0" iyy="0.01" iyz="0" izz="0.01"/>
    </inertial>

    <visual name="shaft">
      <origin xyz="0 0 0" rpy="0 0 0"/> <origin xyz="0 0 0" rpy="1.570796325 0 0"/> <geometry>
        <cylinder radius="0.02" length="0.25"/> </geometry>
      <material name="grey_metal"/>
    </visual>
    <collision name="shaft_collision">
      <origin xyz="0 0 0" rpy="1.570796325 0 0"/>
      <geometry>
        <cylinder radius="0.02" length="0.25"/>
      </geometry>
    </collision>

    <visual name="cam_body">
      <origin xyz="0.035 0 0" rpy="0 0 0"/> <geometry>
        <cylinder radius="0.07" length="0.04"/> </geometry>
      <material name="pink"/>
    </visual>
    <collision name="cam_body_collision">
      <origin xyz="0.035 0 0" rpy="0 0 0"/>
      <geometry>
        <cylinder radius="0.07" length="0.04"/>
      </geometry>
    </collision>

    <visual name="crank_arm">
      <origin xyz="0 -0.145 0.05" rpy="0 0 0"/> <geometry>
        <box size="0.03 0.04 0.1"/>
      </geometry>
      <material name="blue"/>
    </visual>
    <collision name="crank_arm_collision">
      <origin xyz="0 -0.145 0.05" rpy="0 0 0"/>
      <geometry>
        <box size="0.03 0.04 0.1"/>
      </geometry>
    </collision>

    <visual name="crank_handle">
      <origin xyz="0 -0.145 0.1" rpy="1.570796325 0 0"/> <geometry>
        <cylinder radius="0.02" length="0.08"/> </geometry>
      <material name="yellow_handle"/>
    </visual>
    <collision name="crank_handle_collision">
      <origin xyz="0 -0.145 0.1" rpy="1.570796325 0 0"/>
      <geometry>
        <cylinder radius="0.02" length="0.08"/>
      </geometry>
    </collision>
  </link>

  <link name="follower_rod_link">
    <inertial>
      <mass value="0.18"/>
      <origin xyz="0 0 0.075"/> <inertia ixx="0.001" ixy="0" ixz="0" iyy="0.001" iyz="0" izz="0.001"/>
    </inertial>
    <visual name="rod">
      <origin xyz="0 0 0.075" rpy="0 0 0"/> <geometry>
        <cylinder radius="0.015" length="0.15"/> </geometry>
      <material name="blue"/>
    </visual>
    <collision name="rod_collision">
      <origin xyz="0 0 0.075" rpy="0 0 0"/>
      <geometry>
        <cylinder radius="0.015" length="0.15"/>
      </geometry>
    </collision>
  </link>

  <link name="follower_roller_link">
    <inertial>
      <mass value="0.05"/>
      <origin xyz="0 0 0"/> <inertia ixx="0.0001" ixy="0" ixz="0" iyy="0.0001" iyz="0" izz="0.0001"/>
    </inertial>
    <visual name="roller">
      <origin xyz="0 0 0" rpy="0 1.570796325 0"/> <geometry>
        <cylinder radius="0.025" length="0.04"/> </geometry>
      <material name="light_blue_roller"/>
    </visual>
    <collision name="roller_collision">
      <origin xyz="0 0 0" rpy="0 1.570796325 0"/>
      <geometry>
        <cylinder radius="0.025" length="0.04"/>
      </geometry>
    </collision>
  </link>

  <joint name="cam_joint" type="revolute">
    <parent link="base_link"/>
    <child link="cam_assembly_link"/>
    <origin xyz="0 0 0.1" rpy="0 0 0"/> <axis xyz="0 1 0"/> <limit effort="100" velocity="10" lower="-6.2831853" upper="6.2831853"/> <dynamics damping="0.1" friction="0.5"/>
  </joint>

  <joint name="follower_rod_joint" type="prismatic">
    <parent link="base_link"/>
    <child link="follower_rod_link"/>
    <origin xyz="0.035 0 0.09" rpy="0 0 0"/> <axis xyz="0 0 1"/> <limit effort="100" velocity="1.0" lower="0.0" upper="0.07"/>
    <dynamics damping="0.2" friction="0.1"/>
  </joint>

  <joint name="follower_roller_joint" type="continuous">
    <parent link="follower_rod_link"/>
    <child link="follower_roller_link"/>
    <origin xyz="0 0 0" rpy="0 0 0"/>
    <axis xyz="1 0 0"/> <dynamics damping="0.01" friction="0.01"/>
  </joint>

</robot>